2021-11-03, 16:59:34 | ERROR
Traceback (most recent call last):
  File "/home/kennytalarico/Dropbox/School/Code/410/to_ipa.py", line 59, in to_ipa
    for syl in syllabifyARPA(arpa):
  File "/usr/local/lib/python3.8/dist-packages/syllabifier-0.0.1-py3.8.egg/syllabifier/syllabifyARPA.py", line 65, in syllabifyARPA
    handleError('Input %s contains non-ARPABET phones' % word)
  File "/usr/local/lib/python3.8/dist-packages/syllabifier-0.0.1-py3.8.egg/syllabifier/syllabifyARPA.py", line 50, in handleError
    raise ValueError(string)
ValueError: Input '   B AW1 T contains non-ARPABET phones

During handling of the above exception, another exception occurred:

Traceback (most recent call last):
  File "/usr/lib/python3.8/threading.py", line 932, in _bootstrap_inner
    self.run()
  File "/usr/lib/python3.8/threading.py", line 870, in run
    self._target(*self._args, **self._kwargs)
  File "main.py", line 47, in process_input
    ipa_names = [self.ipa_model.to_ipa(name)[1:-1] for name in names]
  File "main.py", line 47, in <listcomp>
    ipa_names = [self.ipa_model.to_ipa(name)[1:-1] for name in names]
  File "/home/kennytalarico/Dropbox/School/Code/410/to_ipa.py", line 67, in to_ipa
    word += self.arpabet_to_ipa_mapping[phone[:2]]
KeyError: "'"

2021-11-07, 13:04:14 | ERROR
Traceback (most recent call last):
  File "/usr/lib/python3.8/threading.py", line 932, in _bootstrap_inner
    self.run()
  File "/usr/lib/python3.8/threading.py", line 870, in run
    self._target(*self._args, **self._kwargs)
  File "main.py", line 78, in process_input
    pd.DataFrame(final_scores)],
NameError: name 'final_scores' is not defined

2021-11-07, 13:04:40 | ERROR
Traceback (most recent call last):
  File "/usr/lib/python3.8/threading.py", line 932, in _bootstrap_inner
    self.run()
  File "/usr/lib/python3.8/threading.py", line 870, in run
    self._target(*self._args, **self._kwargs)
  File "main.py", line 78, in process_input
    pd.DataFrame(final_scores)],
NameError: name 'final_scores' is not defined

2021-11-07, 23:30:48 | ERROR
Traceback (most recent call last):
  File "C:\Program Files\WindowsApps\PythonSoftwareFoundation.Python.3.8_3.8.2800.0_x64__qbz5n2kfra8p0\lib\threading.py", line 932, in _bootstrap_inner
    self.run()
  File "C:\Program Files\WindowsApps\PythonSoftwareFoundation.Python.3.8_3.8.2800.0_x64__qbz5n2kfra8p0\lib\threading.py", line 870, in run
    self._target(*self._args, **self._kwargs)
  File "main.py", line 76, in process_input
    * 100, 2) for i in range(len(ngrams_scores))]
NameError: name 'ngrams_scores' is not defined

2021-11-07, 23:31:40 | ERROR
Traceback (most recent call last):
  File "C:\Program Files\WindowsApps\PythonSoftwareFoundation.Python.3.8_3.8.2800.0_x64__qbz5n2kfra8p0\lib\threading.py", line 932, in _bootstrap_inner
    self.run()
  File "C:\Program Files\WindowsApps\PythonSoftwareFoundation.Python.3.8_3.8.2800.0_x64__qbz5n2kfra8p0\lib\threading.py", line 870, in run
    self._target(*self._args, **self._kwargs)
  File "main.py", line 76, in process_input
    * 100, 2) for i in range(len(bigrams_letters))]
NameError: name 'bigrams_letters' is not defined

2021-11-07, 23:58:36 | ERROR
Traceback (most recent call last):
  File "C:\Program Files\WindowsApps\PythonSoftwareFoundation.Python.3.8_3.8.2800.0_x64__qbz5n2kfra8p0\lib\threading.py", line 932, in _bootstrap_inner
    self.run()
  File "C:\Program Files\WindowsApps\PythonSoftwareFoundation.Python.3.8_3.8.2800.0_x64__qbz5n2kfra8p0\lib\threading.py", line 870, in run
    self._target(*self._args, **self._kwargs)
  File "main.py", line 92, in process_input
    print(result)
NameError: name 'result' is not defined

